<?xml version="1.0" encoding="utf-8"?>
<!-- This URDF was automatically created by SolidWorks to URDF Exporter! Originally created by Stephen Brawner (brawner@gmail.com) 
     Commit Version: 1.6.0-4-g7f85cfe  Build Version: 1.6.7995.38578
     For more information, please see http://wiki.ros.org/sw_urdf_exporter -->
<robot
  name="Robot_URDF">
  <link
    name="base_link">
    <inertial>
      <origin
        xyz="-0.01681 5.7246E-17 0.033683"
        rpy="0 0 0" />
      <mass
        value="0.37245" />
      <inertia
        ixx="0.00026288"
        ixy="-2.4081E-18"
        ixz="-4.2095E-06"
        iyy="0.0005837"
        iyz="6.3701E-19"
        izz="0.00078149" />
    </inertial>
    <visual>
      <origin
        xyz="0 0 0"
        rpy="0 0 0" />
      <geometry>
        <mesh
          filename="package://Robot_URDF/meshes/base_link.STL" />
      </geometry>
      <material
        name="">
        <color
          rgba="1 0 0 1" />
      </material>
    </visual>
    <collision>
      <origin
        xyz="0 0 0"
        rpy="0 0 0" />
      <geometry>
        <mesh
          filename="package://Robot_URDF/meshes/base_link.STL" />
      </geometry>
    </collision>
  </link>
  <link
    name="Link_01">
    <inertial>
      <origin
        xyz="0.012907 -0.0010468 0.12263"
        rpy="0 0 0" />
      <mass
        value="0.23518" />
      <inertia
        ixx="0.00013068"
        ixy="-1.7539E-05"
        ixz="-2.9663E-05"
        iyy="0.00031301"
        iyz="8.0204E-06"
        izz="0.00028226" />
    </inertial>
    <visual>
      <origin
        xyz="0 0 0"
        rpy="0 0 0" />
      <geometry>
        <mesh
          filename="package://Robot_URDF/meshes/Link_01.STL" />
      </geometry>
      <material
        name="">
        <color
          rgba="0.79216 0.81961 0.93333 1" />
      </material>
    </visual>
    <collision>
      <origin
        xyz="0 0 0"
        rpy="0 0 0" />
      <geometry>
        <mesh
          filename="package://Robot_URDF/meshes/Link_01.STL" />
      </geometry>
    </collision>
  </link>
  <joint
    name="Joint_01"
    type="revolute">
    <origin
      xyz="0 0 0"
      rpy="0 0 0" />
    <parent
      link="base_link" />
    <child
      link="Link_01" />
    <axis
      xyz="0 0 1" />
    <limit
      lower="-3.142"
      upper="3.142"
      effort="300"
      velocity="3" />
  </joint>
  <link
    name="Link_02">
    <inertial>
      <origin
        xyz="0.037446 -0.039857 0.18678"
        rpy="0 0 0" />
      <mass
        value="0.22611" />
      <inertia
        ixx="0.00071193"
        ixy="-2.3124E-08"
        ixz="1.0948E-06"
        iyy="0.00077193"
        iyz="9.8911E-06"
        izz="7.9191E-05" />
    </inertial>
    <visual>
      <origin
        xyz="0 0 0"
        rpy="0 0 0" />
      <geometry>
        <mesh
          filename="package://Robot_URDF/meshes/Link_02.STL" />
      </geometry>
      <material
        name="">
        <color
          rgba="0.79216 0.81961 0.93333 1" />
      </material>
    </visual>
    <collision>
      <origin
        xyz="0 0 0"
        rpy="0 0 0" />
      <geometry>
        <mesh
          filename="package://Robot_URDF/meshes/Link_02.STL" />
      </geometry>
    </collision>
  </link>
  <joint
    name="Joint_02"
    type="revolute">
    <origin
      xyz="0 0 0"
      rpy="0 0 0" />
    <parent
      link="Link_01" />
    <child
      link="Link_02" />
    <axis
      xyz="0 1 0" />
    <limit
      lower="-1.57"
      upper="1.57"
      effort="200"
      velocity="3" />
  </joint>
  <link
    name="Link_03">
    <inertial>
      <origin
        xyz="0.03383 -0.0086999 0.30191"
        rpy="0 0 0" />
      <mass
        value="0.15398" />
      <inertia
        ixx="7.1059E-05"
        ixy="2.8189E-06"
        ixz="-3.6573E-06"
        iyy="0.0001078"
        iyz="-6.2512E-06"
        izz="8.6612E-05" />
    </inertial>
    <visual>
      <origin
        xyz="0 0 0"
        rpy="0 0 0" />
      <geometry>
        <mesh
          filename="package://Robot_URDF/meshes/Link_03.STL" />
      </geometry>
      <material
        name="">
        <color
          rgba="0.79216 0.81961 0.93333 1" />
      </material>
    </visual>
    <collision>
      <origin
        xyz="0 0 0"
        rpy="0 0 0" />
      <geometry>
        <mesh
          filename="package://Robot_URDF/meshes/Link_03.STL" />
      </geometry>
    </collision>
  </link>
  <joint
    name="Joint_03"
    type="revolute">
    <origin
      xyz="0 0 0"
      rpy="0 0 0" />
    <parent
      link="Link_02" />
    <child
      link="Link_03" />
    <axis
      xyz="0 -1 0" />
    <limit
      lower="-1.57"
      upper="1.57"
      effort="200"
      velocity="3" />
  </joint>
  <link
    name="Link_04">
    <inertial>
      <origin
        xyz="0.11945 0.000807 0.31037"
        rpy="0 0 0" />
      <mass
        value="0.082509" />
      <inertia
        ixx="2.6186E-05"
        ixy="-9.0856E-07"
        ixz="-3.2953E-08"
        iyy="8.1549E-05"
        iyz="-1.2049E-08"
        izz="8.8551E-05" />
    </inertial>
    <visual>
      <origin
        xyz="0 0 0"
        rpy="0 0 0" />
      <geometry>
        <mesh
          filename="package://Robot_URDF/meshes/Link_04.STL" />
      </geometry>
      <material
        name="">
        <color
          rgba="0.79216 0.81961 0.93333 1" />
      </material>
    </visual>
    <collision>
      <origin
        xyz="0 0 0"
        rpy="0 0 0" />
      <geometry>
        <mesh
          filename="package://Robot_URDF/meshes/Link_04.STL" />
      </geometry>
    </collision>
  </link>
  <joint
    name="Joint_04"
    type="revolute">
    <origin
      xyz="0 0 0"
      rpy="0 0 0" />
    <parent
      link="Link_03" />
    <child
      link="Link_04" />
    <axis
      xyz="1 0 0" />
    <limit
      lower="-3.142"
      upper="3.142"
      effort="200"
      velocity="3" />
  </joint>
  <link
    name="Link_05">
    <inertial>
      <origin
        xyz="0.17291 0.00072078 0.31038"
        rpy="0 0 0" />
      <mass
        value="0.0058433" />
      <inertia
        ixx="9.7352E-07"
        ixy="3.1913E-21"
        ixz="-1.4861E-22"
        iyy="6.7237E-07"
        iyz="2.2772E-21"
        izz="1.177E-06" />
    </inertial>
    <visual>
      <origin
        xyz="0 0 0"
        rpy="0 0 0" />
      <geometry>
        <mesh
          filename="package://Robot_URDF/meshes/Link_05.STL" />
      </geometry>
      <material
        name="">
        <color
          rgba="0.79216 0.81961 0.93333 1" />
      </material>
    </visual>
    <collision>
      <origin
        xyz="0 0 0"
        rpy="0 0 0" />
      <geometry>
        <mesh
          filename="package://Robot_URDF/meshes/Link_05.STL" />
      </geometry>
    </collision>
  </link>
  <joint
    name="Joint_05"
    type="revolute">
    <origin
      xyz="0 0 0"
      rpy="0 0 0" />
    <parent
      link="Link_04" />
    <child
      link="Link_05" />
    <axis
      xyz="0 1 0" />
    <limit
      lower="-3.142"
      upper="3.142"
      effort="200"
      velocity="3" />
  </joint>
  <link
    name="Link_06">
    <inertial>
      <origin
        xyz="0.16788 2.3453E-15 0.31038"
        rpy="0 0 0" />
      <mass
        value="0.013337" />
      <inertia
        ixx="8.4792E-07"
        ixy="-4.7069E-21"
        ixz="-1.8058E-21"
        iyy="1.466E-06"
        iyz="3.7668E-10"
        izz="1.4832E-06" />
    </inertial>
    <visual>
      <origin
        xyz="0 0 0"
        rpy="0 0 0" />
      <geometry>
        <mesh
          filename="package://Robot_URDF/meshes/Link_06.STL" />
      </geometry>
      <material
        name="">
        <color
          rgba="0.79216 0.81961 0.93333 1" />
      </material>
    </visual>
    <collision>
      <origin
        xyz="0 0 0"
        rpy="0 0 0" />
      <geometry>
        <mesh
          filename="package://Robot_URDF/meshes/Link_06.STL" />
      </geometry>
    </collision>
  </link>
  <joint
    name="Joint_06"
    type="revolute">
    <origin
      xyz="0 0 0"
      rpy="0 0 0" />
    <parent
      link="Link_05" />
    <child
      link="Link_06" />
    <axis
      xyz="1 0 0" />
    <limit
      lower="-3.142"
      upper="3.142"
      effort="200"
      velocity="3" />
  </joint>
</robot>