<?xml version="1.0" encoding="utf-8"?>
<!-- This URDF was automatically created by SolidWorks to URDF Exporter! Originally created by Stephen Brawner (brawner@gmail.com) 
     Commit Version: 1.6.0-4-g7f85cfe  Build Version: 1.6.7995.38578
     For more information, please see http://wiki.ros.org/sw_urdf_exporter -->
<robot
  name="URDF">
  <link
    name="base_link">
    <inertial>
      <origin
        xyz="0.1276 0.015439 0.043403"
        rpy="0 0 0" />
      <mass
        value="0.37245" />
      <inertia
        ixx="0.00026288"
        ixy="-2.4098E-18"
        ixz="-4.2095E-06"
        iyy="0.0005837"
        iyz="6.3591E-19"
        izz="0.00078149" />
    </inertial>
    <visual>
      <origin
        xyz="0 0 0"
        rpy="0 0 0" />
      <geometry>
        <mesh
          filename="meshes/base_link.STL" />
      </geometry>
      <material
        name="">
        <color
          rgba="1 0 0 1" />
      </material>
    </visual>
    <collision>
      <origin
        xyz="0 0 0"
        rpy="0 0 0" />
      <geometry>
        <mesh
          filename="meshes/base_link.STL" />
      </geometry>
    </collision>
  </link>
  <link
    name="Link_01">
    <inertial>
      <origin
        xyz="0.0068376 -0.042633 -0.010997"
        rpy="0 0 0" />
      <mass
        value="0.23518" />
      <inertia
        ixx="0.0002317"
        ixy="1.1201E-05"
        ixz="9.2315E-05"
        iyy="0.00028226"
        iyz="-2.8614E-05"
        izz="0.00021199" />
    </inertial>
    <visual>
      <origin
        xyz="0 0 0"
        rpy="0 0 0" />
      <geometry>
        <mesh
          filename="meshes/Link_01.STL" />
      </geometry>
      <material
        name="">
        <color
          rgba="0.79216 0.81961 0.93333 1" />
      </material>
    </visual>
    <collision>
      <origin
        xyz="0 0 0"
        rpy="0 0 0" />
      <geometry>
        <mesh
          filename="meshes/Link_01.STL" />
      </geometry>
    </collision>
  </link>
  <joint
    name="Joint_01"
    type="revolute">
    <origin
      xyz="0.14441 -0.089719 0.015439"
      rpy="0 -0.93212 0" />
    <parent
      link="base_link" />
    <child
      link="Link_01" />
    <axis
      xyz="0 1 0" />
    <limit
      lower="-1.57"
      upper="1.57"
      effort="10"
      velocity="100" />
  </joint>
  <link
    name="Link_02">
    <inertial>
      <origin
        xyz="0.044538 0.025651 -0.02002"
        rpy="0 0 0" />
      <mass
        value="0.22611" />
      <inertia
        ixx="0.00023643"
        ixy="-0.00027344"
        ixz="8.5775E-06"
        iyy="0.00055469"
        iyz="4.9255E-06"
        izz="0.00077193" />
    </inertial>
    <visual>
      <origin
        xyz="0 0 0"
        rpy="0 0 0" />
      <geometry>
        <mesh
          filename="meshes/Link_02.STL" />
      </geometry>
      <material
        name="">
        <color
          rgba="0.79216 0.81961 0.93333 1" />
      </material>
    </visual>
    <collision>
      <origin
        xyz="0 0 0"
        rpy="0 0 0" />
      <geometry>
        <mesh
          filename="meshes/Link_02.STL" />
      </geometry>
    </collision>
  </link>
  <joint
    name="Joint_02"
    type="revolute">
    <origin
      xyz="0.0063657 -0.05538 -0.041943"
      rpy="-0.86144 -0.41923 -1.907" />
    <parent
      link="Link_01" />
    <child
      link="Link_02" />
    <axis
      xyz="0 0 1" />
    <limit
      lower="0"
      upper="0"
      effort="0"
      velocity="0" />
  </joint>
  <link
    name="Link_03">
    <inertial>
      <origin
        xyz="-0.0111371491141937 -0.00652959951672732 -0.00366986536105676"
        rpy="0 0 0" />
      <mass
        value="0.153983626744783" />
      <inertia
        ixx="0.000107798366860628"
        ixy="-6.25124107879708E-06"
        ixz="-2.81887226871874E-06"
        iyy="8.6612329750608E-05"
        iyz="3.65733699147981E-06"
        izz="7.10591801370458E-05" />
    </inertial>
    <visual>
      <origin
        xyz="0 0 0"
        rpy="0 0 0" />
      <geometry>
        <mesh
          filename="meshes/Link_03.STL" />
      </geometry>
      <material
        name="">
        <color
          rgba="0.792156862745098 0.819607843137255 0.933333333333333 1" />
      </material>
    </visual>
    <collision>
      <origin
        xyz="0 0 0"
        rpy="0 0 0" />
      <geometry>
        <mesh
          filename="meshes/Link_03.STL" />
      </geometry>
    </collision>
  </link>
  <joint
    name="Joint_03"
    type="revolute">
    <origin
      xyz="0.13856 0.08 0"
      rpy="2.096 1.5708 0" />
    <parent
      link="Link_02" />
    <child
      link="Link_03" />
    <axis
      xyz="1 0 0" />
    <limit
      lower="0"
      upper="0"
      effort="0"
      velocity="0" />
  </joint>
  <link
    name="Link_04">
    <inertial>
      <origin
        xyz="0.000807 -1.0286E-05 0.048156"
        rpy="0 0 0" />
      <mass
        value="0.082509" />
      <inertia
        ixx="8.1549E-05"
        ixy="-1.2049E-08"
        ixz="-9.0856E-07"
        iyy="8.8551E-05"
        iyz="-3.2953E-08"
        izz="2.6186E-05" />
    </inertial>
    <visual>
      <origin
        xyz="0 0 0"
        rpy="0 0 0" />
      <geometry>
        <mesh
          filename="meshes/Link_04.STL" />
      </geometry>
      <material
        name="">
        <color
          rgba="0.79216 0.81961 0.93333 1" />
      </material>
    </visual>
    <collision>
      <origin
        xyz="0 0 0"
        rpy="0 0 0" />
      <geometry>
        <mesh
          filename="meshes/Link_04.STL" />
      </geometry>
    </collision>
  </link>
  <joint
    name="Joint_04"
    type="revolute">
    <origin
      xyz="-0.019837 -0.015 0.033795"
      rpy="0 0 0.026295" />
    <parent
      link="Link_03" />
    <child
      link="Link_04" />
    <axis
      xyz="0 0 1" />
    <limit
      lower="0"
      upper="0"
      effort="0"
      velocity="0" />
  </joint>
  <link
    name="Link_05">
    <inertial>
      <origin
        xyz="-0.00072078 -6.1617E-15 -0.0068092"
        rpy="0 0 0" />
      <mass
        value="0.0058433" />
      <inertia
        ixx="6.7237E-07"
        ixy="-4.3013E-22"
        ixz="1.3617E-22"
        iyy="1.177E-06"
        iyz="-1.0588E-22"
        izz="9.7352E-07" />
    </inertial>
    <visual>
      <origin
        xyz="0 0 0"
        rpy="0 0 0" />
      <geometry>
        <mesh
          filename="meshes/Link_05.STL" />
      </geometry>
      <material
        name="">
        <color
          rgba="0.79216 0.81961 0.93333 1" />
      </material>
    </visual>
    <collision>
      <origin
        xyz="0 0 0"
        rpy="0 0 0" />
      <geometry>
        <mesh
          filename="meshes/Link_05.STL" />
      </geometry>
    </collision>
  </link>
  <joint
    name="Joint_05"
    type="revolute">
    <origin
      xyz="0 0 0.094805"
      rpy="-3.0417 0 -3.1416" />
    <parent
      link="Link_04" />
    <child
      link="Link_05" />
    <axis
      xyz="1 0 0" />
    <limit
      lower="0"
      upper="0"
      effort="0"
      velocity="0" />
  </joint>
  <link
    name="Link_06">
    <inertial>
      <origin
        xyz="-1.1657E-14 -1.3878E-17 0.015597"
        rpy="0 0 0" />
      <mass
        value="0.012402" />
      <inertia
        ixx="1.4251E-06"
        ixy="6.6174E-23"
        ixz="2.4352E-21"
        iyy="1.4251E-06"
        iyz="2.3161E-22"
        izz="8.0237E-07" />
    </inertial>
    <visual>
      <origin
        xyz="0 0 0"
        rpy="0 0 0" />
      <geometry>
        <mesh
          filename="meshes/Link_06.STL" />
      </geometry>
      <material
        name="">
        <color
          rgba="0.79216 0.81961 0.93333 1" />
      </material>
    </visual>
    <collision>
      <origin
        xyz="0 0 0"
        rpy="0 0 0" />
      <geometry>
        <mesh
          filename="meshes/Link_06.STL" />
      </geometry>
    </collision>
  </link>
  <joint
    name="Joint_06"
    type="revolute">
    <origin
      xyz="0 0 0.0158"
      rpy="3.1416 0 1.5708" />
    <parent
      link="Link_05" />
    <child
      link="Link_06" />
    <axis
      xyz="0 0 0" />
    <limit
      lower="0"
      upper="0"
      effort="0"
      velocity="0" />
  </joint>
  <link
    name="End_Effector">
    <inertial>
      <origin
        xyz="3.4694E-18 0.0057126 -1.1102E-16"
        rpy="0 0 0" />
      <mass
        value="0.0009357" />
      <inertia
        ixx="4.0879E-08"
        ixy="8.3752E-24"
        ixz="1.2408E-24"
        iyy="4.5548E-08"
        iyz="2.192E-23"
        izz="5.8075E-08" />
    </inertial>
    <visual>
      <origin
        xyz="0 0 0"
        rpy="0 0 0" />
      <geometry>
        <mesh
          filename="meshes/End_Effector.STL" />
      </geometry>
      <material
        name="">
        <color
          rgba="0.79216 0.81961 0.93333 1" />
      </material>
    </visual>
    <collision>
      <origin
        xyz="0 0 0"
        rpy="0 0 0" />
      <geometry>
        <mesh
          filename="meshes/End_Effector.STL" />
      </geometry>
    </collision>
  </link>
  <joint
    name="End_Effector_Joint"
    type="fixed">
    <origin
      xyz="0 0 0.038131"
      rpy="1.5708 0 -1.6911" />
    <parent
      link="Link_06" />
    <child
      link="End_Effector" />
    <axis
      xyz="0 0 0" />
  </joint>
</robot>